Workbook

Sheet EMPLOYEES
A1: EMPLOYEE ID | B1: FULL NAME | C1: DEPARTMENT
A2: CRD/24/00003 | B2: Lawrence Komolafe | C2: Chief Operating Officer
A3: CRD/25/00067 | B3: Abdulkadir Ahmad | C3: Recovery
A4: CRD/25/00084 | B4: Abdullahi Zainab Mohammed | C4: Customer Experience
A5: CRD/25/00043 | B5: Abdulrasaq Aishat Ajoke | C5: Merchant Acquisition
A6: CRD/24/00017 | B6: Abolarin Segun Emmanuel | C6: Business operation and strategic
A7: CRD/24/00014 | B7: Adam Abdulateef | C7: Recovery
A8: CRD/26/00119 | B8: Adebayo Faith Oluwashikemi | C8: Recovery
A9: CRD/26/00120 | B9: Adebayo Femi Ebenezer | C9: Collection
A10: CRD/25/00041 | B10: Adebayo John Olushola | C10: Loan Assessement and Approval
A11: CRD/25/00083 | B11: Adebayo Samuel Kehinde | C11: Risk and Compliance
A12: CRD/26/00121 | B12: Adedayo Olajumoke | C12: Collection
... A104: CRD/26/00144 | B104: Kudirat Brown-Birena | C104: Marketing

Sheet LEAVE LOG
A1: EMPLOYEE ID | B1: EMPLOYEE NAME | C1: LEAVE TYPE | D1: START DATE | E1: END DATE | F1: DAYS | G1: STATUS
A2: CRD/25/00030 | B2: =IFERROR(VLOOKUP(A2,EMPLOYEES!A:B,2,FALSE),"") -> Boluwatife Omoniyi | C2: Sick Leave | D2: 46057 | E2: 46059 | F2: =E2-D2 -> 2 | G2: Approved
A3: CRD/25/00040 | B3: =IFERROR(VLOOKUP(A3,EMPLOYEES!A:B,2,FALSE),"") -> Johnson olajumoke Grace | C3: Sick Leave | D3: 46127 | E3: 46128 | F3: =E3-D3 -> 1 | G3: Approved
A4: CRD/24/00005 | B4: =IFERROR(VLOOKUP(A4,EMPLOYEES!A:B,2,FALSE),"") -> Joseph Olayemi | C4: Sick Leave | D4: 46058 | E4: 46063 | F4: =E4-D4 -> 5 | G4: Approved
A5: CRD/25/00038 | B5: =IFERROR(VLOOKUP(A5,EMPLOYEES!A:B,2,FALSE),"") -> Azeezat Adebayo Oluwabukola | C5: Annual Leave | D5: 46081 | E5: 46091 | F5: =E5-D5 -> 10 | G5: Approved
A6: CRD/25/00038 | B6: =IFERROR(VLOOKUP(A6,EMPLOYEES!A:B,2,FALSE),"") -> Azeezat Adebayo Oluwabukola | C6: Sick Leave | D6: 46091 | E6: 46096 | F6: =E6-D6 -> 5 | G6: Approved
A7: CRD/25/00074 | B7: =IFERROR(VLOOKUP(A7,EMPLOYEES!A:B,2,FALSE),"") -> Olaseni Blessing Elizabeth | C7: Annual Leave | D7: 46062 | E7: 46064 | F7: =E7-D7 -> 2 | G7: Approved
A8: CRD/25/00024 | B8: =IFERROR(VLOOKUP(A8,EMPLOYEES!A:B,2,FALSE),"") -> Olagunju Aishat Olaide | C8: Sick Leave | D8: 46086 | E8: 46091 | F8: =E8-D8 -> 5 | G8: Approved
A9: CRD/24/00006 | B9: =IFERROR(VLOOKUP(A9,EMPLOYEES!A:B,2,FALSE),"") -> Adepoju Rachael Omotayo | C9: Maternity Leave | D9: 46055 | E9: 46145 | F9: =E9-D9 -> 90 | G9: Approved
A10: CRD/24/00006 | B10: =IFERROR(VLOOKUP(A10,EMPLOYEES!A:B,2,FALSE),"") -> Adepoju Rachael Omotayo | C10: Sick Leave | D10: 46048 | E10: 46053 | F10: =E10-D10 -> 5 | G10: Approved
A11: CRD/24/00006 | B11: =IFERROR(VLOOKUP(A11,EMPLOYEES!A:B,2,FALSE),"") -> Adepoju Rachael Omotayo | C11: Annual Leave | D11: 46040 | E11: 46046 | F11: =E11-D11 -> 6 | G11: Approved
A12: CRD/25/00089 | B12: =IFERROR(VLOOKUP(A12,EMPLOYEES!A:B,2,FALSE),"") -> Adeyemo Adeola Dorcas | C12: Annual Leave | D12: 46039 | E12: 46041 | F12: =E12-D12 -> 2 | G12: Approved
A13: CRD/25/00089 | B13: =IFERROR(VLOOKUP(A13,EMPLOYEES!A:B,2,FALSE),"") -> Adeyemo Adeola Dorcas | C13: Sick Leave | D13: 46128 | E13: 46130 | F13: =E13-D13 -> 2 | G13: Approved
A14: CRD/25/00091 | B14: Sulyman Muftau Aremu | C14: Sick Leave | D14: 46085 | E14: 46087 | F14: =E14-D14 -> 2 | G14: Approved
A15: CRD/25/00084 | B15: =IFERROR(VLOOKUP(A15,EMPLOYEES!A:B,2,FALSE),"") -> Abdullahi Zainab Mohammed | C15: Sick Leave | D15: 46070 | E15: 46072 | F15: =E15-D15 -> 2 | G15: Approved
A16: CRD/25/00084 | B16: =IFERROR(VLOOKUP(A16,EMPLOYEES!A:B,2,FALSE),"") -> Abdullahi Zainab Mohammed | C16: Annual Leave | D16: 46099 | E16: 46105 | F16: =E16-D16 -> 6 | G16: Approved
A17: CRD/25/00061 | B17: =IFERROR(VLOOKUP(A17,EMPLOYEES!A:B,2,FALSE),"") -> OLADOSU KEHINDE MARY | C17: Sick Leave | D17: 46079 | E17: 46080 | F17: =E17-D17 -> 1 | G17: Approved
A18: CRD/25/00061 | B18: =IFERROR(VLOOKUP(A18,EMPLOYEES!A:B,2,FALSE),"") -> OLADOSU KEHINDE MARY | C18: Sick Leave | D18: 46128 | E18: 46129 | F18: =E18-D18 -> 1 | G18: Approved
A19: CRD/25/00064 | B19: =IFERROR(VLOOKUP(A19,EMPLOYEES!A:B,2,FALSE),"") -> Ogidiolu Oluwashina Daniel | C19: Sick Leave | D19: 46071 | E19: 46073 | F19: =E19-D19 -> 2 | G19: Approved
A20: CRD/25/00029 | B20: =IFERROR(VLOOKUP(A20,EMPLOYEES!A:B,2,FALSE),"") -> Sulyman Muftau Aremu | C20: Annual Leave | D20: 46121 | E20: 46123 | F20: =E20-D20 -> 2 | G20: Approved
A21: CRD/25/00087 | B21: =IFERROR(VLOOKUP(A21,EMPLOYEES!A:B,2,FALSE),"") -> Oluwatobi Samuel Kolawole | C21: Sick Leave | D21: 46064 | E21: 46065 | F21: =E21-D21 -> 1 | G21: Approved
A22: CRD/25/00087 | B22: =IFERROR(VLOOKUP(A22,EMPLOYEES!A:B,2,FALSE),"") -> Oluwatobi Samuel Kolawole | C22: Annual Leave | D22: 46073 | E22: 46076 | F22: =E22-D22 -> 3 | G22: Approved
A23: CRD/25/00087 | B23: =IFERROR(VLOOKUP(A23,EMPLOYEES!A:B,2,FALSE),"") -> Oluwatobi Samuel Kolawole | C23: Marital Leave | D23: 46092 | E23: 46113 | F23: =E23-D23 -> 21 | G23: Approved
A24: CRD/25/00088 | B24: =IFERROR(VLOOKUP(A24,EMPLOYEES!A:B,2,FALSE),"") -> Olufemi Oluwatosin Elizabeth | C24: Sick Leave | D24: 46074 | E24: 46077 | F24: =E24-D24 -> 3 | G24: Approved
A25: CRD/25/00088 | B25: =IFERROR(VLOOKUP(A25,EMPLOYEES!A:B,2,FALSE),"") -> Olufemi Oluwatosin Elizabeth | C25: Sick Leave | D25: 46119 | E25: 46121 | F25: =E25-D25 -> 2 | G25: Approved
A26: CRD/26/00139 | B26: =IFERROR(VLOOKUP(A26,EMPLOYEES!A:B,2,FALSE),"") -> Olatunji Dorcas | C26: Annual Leave | D26: 46118 | E26: 46123 | F26: =E26-D26 -> 5 | G26: Approved
... A31: CRD/25/00030 | B31: =IFERROR(VLOOKUP(A31,EMPLOYEES!A:B,2,FALSE),"") -> Boluwatife Omoniyi | C31: Sick Leave | D31: 46129 | E31: 46130 | F31: =E31-D31 -> 1 | G31: Approved
B32: =IFERROR(VLOOKUP(A32,EMPLOYEES!A:B,2,FALSE),"") | F32: =E32-D32 -> 0
B33: =IFERROR(VLOOKUP(A33,EMPLOYEES!A:B,2,FALSE),"") | F33: =E33-D33 -> 0
B34: =IFERROR(VLOOKUP(A34,EMPLOYEES!A:B,2,FALSE),"") | F34: =E34-D34 -> 0
B35: =IFERROR(VLOOKUP(A35,EMPLOYEES!A:B,2,FALSE),"") | F35: =E35-D35 -> 0
B36: =IFERROR(VLOOKUP(A36,EMPLOYEES!A:B,2,FALSE),"") | F36: =E36-D36 -> 0
B37: =IFERROR(VLOOKUP(A37,EMPLOYEES!A:B,2,FALSE),"") | F37: =E37-D37 -> 0
B38: =IFERROR(VLOOKUP(A38,EMPLOYEES!A:B,2,FALSE),"") | F38: =E38-D38 -> 0
B39: =IFERROR(VLOOKUP(A39,EMPLOYEES!A:B,2,FALSE),"") | F39: =E39-D39 -> 0
B40: =IFERROR(VLOOKUP(A40,EMPLOYEES!A:B,2,FALSE),"") | F40: =E40-D40 -> 0
B41: =IFERROR(VLOOKUP(A41,EMPLOYEES!A:B,2,FALSE),"") | F41: =E41-D41 -> 0
B42: =IFERROR(VLOOKUP(A42,EMPLOYEES!A:B,2,FALSE),"") | F42: =E42-D42 -> 0
B43: =IFERROR(VLOOKUP(A43,EMPLOYEES!A:B,2,FALSE),"") | F43: =E43-D43 -> 0
... B55: =IFERROR(VLOOKUP(A55,EMPLOYEES!A:B,2,FALSE),"") | F55: =E55-D55 -> 0
...

Sheet SUMMARY
A1: EMPLOYEE NAME | B1: SICK LEAVE USED | C1: SICK LEAVE LEFT | D1: ANNUAL LEAVE USED | E1: ANNUAL LEAVE LEFT | F1: PATERNITY LEAVE | G1: MATERNITY LEAVE | H1: MARITAL LEAVE | I1: COMPASSIONATE LEAVE
A2: =EMPLOYEES!B2 -> Lawrence Komolafe | B2: =SUMIFS('LEAVE LOG'!F$1:F$1048573,'LEAVE LOG'!B$1:B$1048573,A2,'LEAVE LOG'!C$1:C$1048573,"Sick Leave",'LEAVE LOG'!G$1:G$1048573,"Approved") -> 0 | C2: =5-B2 -> 5 | D2: =SUMIFS('LEAVE LOG'!F$1:F$1048573,'LEAVE LOG'!B$1:B$1048573,A2,'LEAVE LOG'!C$1:C$1048573,"Annual Leave",'LEAVE LOG'!G$1:G$1048573,"Approved") -> 0 | E2: =10-D2 -> 10 | F2: =SUMIFS('LEAVE LOG'!F$1:F$1048573,'LEAVE LOG'!B$1:B$1048573,A2,'LEAVE LOG'!C$1:C$1048573,"Paternity Leave",'LEAVE LOG'!G$1:G$1048573,"Approved") -> 0 | G2: =SUMIFS('LEAVE LOG'!F$1:F$1048573,'LEAVE LOG'!B$1:B$1048573,A2,'LEAVE LOG'!C$1:C$1048573,"Maternity Leave",'LEAVE LOG'!G$1:G$1048573,"Approved") -> 0 | H2: =SUMIFS('LEAVE LOG'!F$1:F$1048573,'LEAVE LOG'!B$1:B$1048573,A2,'LEAVE LOG'!C$1:C$1048573,"Marital Leave",'LEAVE LOG'!G$1:G$1048573,"Approved") -> 0 | I2: =SUMIFS('LEAVE LOG'!F$1:F$1048573,'LEAVE LOG'!B$1:B$1048573,A2,'LEAVE LOG'!C$1:C$1048573,"Compassionate Leave",'LEAVE LOG'!G$1:G$1048573,"Approved") -> 0
A3: =EMPLOYEES!B3 -> Abdulkadir Ahmad | B3: =SUMIFS('LEAVE LOG'!F$1:F$1048573,'LEAVE LOG'!B$1:B$1048573,A3,'LEAVE LOG'!C$1:C$1048573,"Sick Leave",'LEAVE LOG'!G$1:G$1048573,"Approved") -> 0 | C3: =5-B3 -> 5 | D3: =SUMIFS('LEAVE LOG'!F$1:F$1048573,'LEAVE LOG'!B$1:B$1048573,A3,'LEAVE LOG'!C$1:C$1048573,"Annual Leave",'LEAVE LOG'!G$1:G$1048573,"Approved") -> 0 | E3: =10-D3 -> 10 | F3: =SUMIFS('LEAVE LOG'!F$1:F$1048573,'LEAVE LOG'!B$1:B$1048573,A3,'LEAVE LOG'!C$1:C$1048573,"Paternity Leave",'LEAVE LOG'!G$1:G$1048573,"Approved") -> 0 | G3: =SUMIFS('LEAVE LOG'!F$1:F$1048573,'LEAVE LOG'!B$1:B$1048573,A3,'LEAVE LOG'!C$1:C$1048573,"Maternity Leave",'LEAVE LOG'!G$1:G$1048573,"Approved") -> 0 | H3: =SUMIFS('LEAVE LOG'!F$1:F$1048573,'LEAVE LOG'!B$1:B$1048573,A3,'LEAVE LOG'!C$1:C$1048573,"Marital Leave",'LEAVE LOG'!G$1:G$1048573,"Approved") -> 0 | I3: =SUMIFS('LEAVE LOG'!F$1:F$1048573,'LEAVE LOG'!B$1:B$1048573,A3,'LEAVE LOG'!C$1:C$1048573,"Compassionate Leave",'LEAVE LOG'!G$1:G$1048573,"Approved") -> 0
A4: =EMPLOYEES!B4 -> Abdullahi Zainab Mohammed | B4: =SUMIFS('LEAVE LOG'!F$1:F$1048573,'LEAVE LOG'!B$1:B$1048573,A4,'LEAVE LOG'!C$1:C$1048573,"Sick Leave",'LEAVE LOG'!G$1:G$1048573,"Approved") -> 2 | C4: =5-B4 -> 3 | D4: =SUMIFS('LEAVE LOG'!F$1:F$1048573,'LEAVE LOG'!B$1:B$1048573,A4,'LEAVE LOG'!C$1:C$1048573,"Annual Leave",'LEAVE LOG'!G$1:G$1048573,"Approved") -> 6 | E4: =10-D4 -> 4 | F4: =SUMIFS('LEAVE LOG'!F$1:F$1048573,'LEAVE LOG'!B$1:B$1048573,A4,'LEAVE LOG'!C$1:C$1048573,"Paternity Leave",'LEAVE LOG'!G$1:G$1048573,"Approved") -> 0 | G4: =SUMIFS('LEAVE LOG'!F$1:F$1048573,'LEAVE LOG'!B$1:B$1048573,A4,'LEAVE LOG'!C$1:C$1048573,"Maternity Leave",'LEAVE LOG'!G$1:G$1048573,"Approved") -> 0 | H4: =SUMIFS('LEAVE LOG'!F$1:F$1048573,'LEAVE LOG'!B$1:B$1048573,A4,'LEAVE LOG'!C$1:C$1048573,"Marital Leave",'LEAVE LOG'!G$1:G$1048573,"Approved") -> 0 | I4: =SUMIFS('LEAVE LOG'!F$1:F$1048573,'LEAVE LOG'!B$1:B$1048573,A4,'LEAVE LOG'!C$1:C$1048573,"Compassionate Leave",'LEAVE LOG'!G$1:G$1048573,"Approved") -> 0
A5: =EMPLOYEES!B5 -> Abdulrasaq Aishat Ajoke | B5: =SUMIFS('LEAVE LOG'!F$1:F$1048573,'LEAVE LOG'!B$1:B$1048573,A5,'LEAVE LOG'!C$1:C$1048573,"Sick Leave",'LEAVE LOG'!G$1:G$1048573,"Approved") -> 0 | C5: =5-B5 -> 5 | D5: =SUMIFS('LEAVE LOG'!F$1:F$1048573,'LEAVE LOG'!B$1:B$1048573,A5,'LEAVE LOG'!C$1:C$1048573,"Annual Leave",'LEAVE LOG'!G$1:G$1048573,"Approved") -> 0 | E5: =10-D5 -> 10 | F5: =SUMIFS('LEAVE LOG'!F$1:F$1048573,'LEAVE LOG'!B$1:B$1048573,A5,'LEAVE LOG'!C$1:C$1048573,"Paternity Leave",'LEAVE LOG'!G$1:G$1048573,"Approved") -> 0 | G5: =SUMIFS('LEAVE LOG'!F$1:F$1048573,'LEAVE LOG'!B$1:B$1048573,A5,'LEAVE LOG'!C$1:C$1048573,"Maternity Leave",'LEAVE LOG'!G$1:G$1048573,"Approved") -> 0 | H5: =SUMIFS('LEAVE LOG'!F$1:F$1048573,'LEAVE LOG'!B$1:B$1048573,A5,'LEAVE LOG'!C$1:C$1048573,"Marital Leave",'LEAVE LOG'!G$1:G$1048573,"Approved") -> 0 | I5: =SUMIFS('LEAVE LOG'!F$1:F$1048573,'LEAVE LOG'!B$1:B$1048573,A5,'LEAVE LOG'!C$1:C$1048573,"Compassionate Leave",'LEAVE LOG'!G$1:G$1048573,"Approved") -> 0
A6: =EMPLOYEES!B6 -> Abolarin Segun Emmanuel | B6: =SUMIFS('LEAVE LOG'!F$1:F$1048573,'LEAVE LOG'!B$1:B$1048573,A6,'LEAVE LOG'!C$1:C$1048573,"Sick Leave",'LEAVE LOG'!G$1:G$1048573,"Approved") -> 0 | C6: =5-B6 -> 5 | D6: =SUMIFS('LEAVE LOG'!F$1:F$1048573,'LEAVE LOG'!B$1:B$1048573,A6,'LEAVE LOG'!C$1:C$1048573,"Annual Leave",'LEAVE LOG'!G$1:G$1048573,"Approved") -> 0 | E6: =10-D6 -> 10 | F6: =SUMIFS('LEAVE LOG'!F$1:F$1048573,'LEAVE LOG'!B$1:B$1048573,A6,'LEAVE LOG'!C$1:C$1048573,"Paternity Leave",'LEAVE LOG'!G$1:G$1048573,"Approved") -> 0 | G6: =SUMIFS('LEAVE LOG'!F$1:F$1048573,'LEAVE LOG'!B$1:B$1048573,A6,'LEAVE LOG'!C$1:C$1048573,"Maternity Leave",'LEAVE LOG'!G$1:G$1048573,"Approved") -> 0 | H6: =SUMIFS('LEAVE LOG'!F$1:F$1048573,'LEAVE LOG'!B$1:B$1048573,A6,'LEAVE LOG'!C$1:C$1048573,"Marital Leave",'LEAVE LOG'!G$1:G$1048573,"Approved") -> 0 | I6: =SUMIFS('LEAVE LOG'!F$1:F$1048573,'LEAVE LOG'!B$1:B$1048573,A6,'LEAVE LOG'!C$1:C$1048573,"Compassionate Leave",'LEAVE LOG'!G$1:G$1048573,"Approved") -> 0
A7: =EMPLOYEES!B7 -> Adam Abdulateef | B7: =SUMIFS('LEAVE LOG'!F$1:F$1048573,'LEAVE LOG'!B$1:B$1048573,A7,'LEAVE LOG'!C$1:C$1048573,"Sick Leave",'LEAVE LOG'!G$1:G$1048573,"Approved") -> 0 | C7: =5-B7 -> 5 | D7: =SUMIFS('LEAVE LOG'!F$1:F$1048573,'LEAVE LOG'!B$1:B$1048573,A7,'LEAVE LOG'!C$1:C$1048573,"Annual Leave",'LEAVE LOG'!G$1:G$1048573,"Approved") -> 0 | E7: =10-D7 -> 10 | F7: =SUMIFS('LEAVE LOG'!F$1:F$1048573,'LEAVE LOG'!B$1:B$1048573,A7,'LEAVE LOG'!C$1:C$1048573,"Paternity Leave",'LEAVE LOG'!G$1:G$1048573,"Approved") -> 0 | G7: =SUMIFS('LEAVE LOG'!F$1:F$1048573,'LEAVE LOG'!B$1:B$1048573,A7,'LEAVE LOG'!C$1:C$1048573,"Maternity Leave",'LEAVE LOG'!G$1:G$1048573,"Approved") -> 0 | H7: =SUMIFS('LEAVE LOG'!F$1:F$1048573,'LEAVE LOG'!B$1:B$1048573,A7,'LEAVE LOG'!C$1:C$1048573,"Marital Leave",'LEAVE LOG'!G$1:G$1048573,"Approved") -> 0 | I7: =SUMIFS('LEAVE LOG'!F$1:F$1048573,'LEAVE LOG'!B$1:B$1048573,A7,'LEAVE LOG'!C$1:C$1048573,"Compassionate Leave",'LEAVE LOG'!G$1:G$1048573,"Approved") -> 0
A8: =EMPLOYEES!B8 -> Adebayo Faith Oluwashikemi | B8: =SUMIFS('LEAVE LOG'!F$1:F$1048573,'LEAVE LOG'!B$1:B$1048573,A8,'LEAVE LOG'!C$1:C$1048573,"Sick Leave",'LEAVE LOG'!G$1:G$1048573,"Approved") -> 0 | C8: =5-B8 -> 5 | D8: =SUMIFS('LEAVE LOG'!F$1:F$1048573,'LEAVE LOG'!B$1:B$1048573,A8,'LEAVE LOG'!C$1:C$1048573,"Annual Leave",'LEAVE LOG'!G$1:G$1048573,"Approved") -> 0 | E8: =10-D8 -> 10 | F8: =SUMIFS('LEAVE LOG'!F$1:F$1048573,'LEAVE LOG'!B$1:B$1048573,A8,'LEAVE LOG'!C$1:C$1048573,"Paternity Leave",'LEAVE LOG'!G$1:G$1048573,"Approved") -> 0 | G8: =SUMIFS('LEAVE LOG'!F$1:F$1048573,'LEAVE LOG'!B$1:B$1048573,A8,'LEAVE LOG'!C$1:C$1048573,"Maternity Leave",'LEAVE LOG'!G$1:G$1048573,"Approved") -> 0 | H8: =SUMIFS('LEAVE LOG'!F$1:F$1048573,'LEAVE LOG'!B$1:B$1048573,A8,'LEAVE LOG'!C$1:C$1048573,"Marital Leave",'LEAVE LOG'!G$1:G$1048573,"Approved") -> 0 | I8: =SUMIFS('LEAVE LOG'!F$1:F$1048573,'LEAVE LOG'!B$1:B$1048573,A8,'LEAVE LOG'!C$1:C$1048573,"Compassionate Leave",'LEAVE LOG'!G$1:G$1048573,"Approved") -> 0
A9: =EMPLOYEES!B9 -> Adebayo Femi Ebenezer | B9: =SUMIFS('LEAVE LOG'!F$1:F$1048573,'LEAVE LOG'!B$1:B$1048573,A9,'LEAVE LOG'!C$1:C$1048573,"Sick Leave",'LEAVE LOG'!G$1:G$1048573,"Approved") -> 0 | C9: =5-B9 -> 5 | D9: =SUMIFS('LEAVE LOG'!F$1:F$1048573,'LEAVE LOG'!B$1:B$1048573,A9,'LEAVE LOG'!C$1:C$1048573,"Annual Leave",'LEAVE LOG'!G$1:G$1048573,"Approved") -> 0 | E9: =10-D9 -> 10 | F9: =SUMIFS('LEAVE LOG'!F$1:F$1048573,'LEAVE LOG'!B$1:B$1048573,A9,'LEAVE LOG'!C$1:C$1048573,"Paternity Leave",'LEAVE LOG'!G$1:G$1048573,"Approved") -> 0 | G9: =SUMIFS('LEAVE LOG'!F$1:F$1048573,'LEAVE LOG'!B$1:B$1048573,A9,'LEAVE LOG'!C$1:C$1048573,"Maternity Leave",'LEAVE LOG'!G$1:G$1048573,"Approved") -> 0 | H9: =SUMIFS('LEAVE LOG'!F$1:F$1048573,'LEAVE LOG'!B$1:B$1048573,A9,'LEAVE LOG'!C$1:C$1048573,"Marital Leave",'LEAVE LOG'!G$1:G$1048573,"Approved") -> 0 | I9: =SUMIFS('LEAVE LOG'!F$1:F$1048573,'LEAVE LOG'!B$1:B$1048573,A9,'LEAVE LOG'!C$1:C$1048573,"Compassionate Leave",'LEAVE LOG'!G$1:G$1048573,"Approved") -> 0
A10: =EMPLOYEES!B10 -> Adebayo John Olushola | B10: =SUMIFS('LEAVE LOG'!F$1:F$1048573,'LEAVE LOG'!B$1:B$1048573,A10,'LEAVE LOG'!C$1:C$1048573,"Sick Leave",'LEAVE LOG'!G$1:G$1048573,"Approved") -> 0 | C10: =5-B10 -> 5 | D10: =SUMIFS('LEAVE LOG'!F$1:F$1048573,'LEAVE LOG'!B$1:B$1048573,A10,'LEAVE LOG'!C$1:C$1048573,"Annual Leave",'LEAVE LOG'!G$1:G$1048573,"Approved") -> 0 | E10: =10-D10 -> 10 | F10: =SUMIFS('LEAVE LOG'!F$1:F$1048573,'LEAVE LOG'!B$1:B$1048573,A10,'LEAVE LOG'!C$1:C$1048573,"Paternity Leave",'LEAVE LOG'!G$1:G$1048573,"Approved") -> 0 | G10: =SUMIFS('LEAVE LOG'!F$1:F$1048573,'LEAVE LOG'!B$1:B$1048573,A10,'LEAVE LOG'!C$1:C$1048573,"Maternity Leave",'LEAVE LOG'!G$1:G$1048573,"Approved") -> 0 | H10: =SUMIFS('LEAVE LOG'!F$1:F$1048573,'LEAVE LOG'!B$1:B$1048573,A10,'LEAVE LOG'!C$1:C$1048573,"Marital Leave",'LEAVE LOG'!G$1:G$1048573,"Approved") -> 0 | I10: =SUMIFS('LEAVE LOG'!F$1:F$1048573,'LEAVE LOG'!B$1:B$1048573,A10,'LEAVE LOG'!C$1:C$1048573,"Compassionate Leave",'LEAVE LOG'!G$1:G$1048573,"Approved") -> 0
A11: =EMPLOYEES!B11 -> Adebayo Samuel Kehinde | B11: =SUMIFS('LEAVE LOG'!F$1:F$1048573,'LEAVE LOG'!B$1:B$1048573,A11,'LEAVE LOG'!C$1:C$1048573,"Sick Leave",'LEAVE LOG'!G$1:G$1048573,"Approved") -> 0 | C11: =5-B11 -> 5 | D11: =SUMIFS('LEAVE LOG'!F$1:F$1048573,'LEAVE LOG'!B$1:B$1048573,A11,'LEAVE LOG'!C$1:C$1048573,"Annual Leave",'LEAVE LOG'!G$1:G$1048573,"Approved") -> 0 | E11: =10-D11 -> 10 | F11: =SUMIFS('LEAVE LOG'!F$1:F$1048573,'LEAVE LOG'!B$1:B$1048573,A11,'LEAVE LOG'!C$1:C$1048573,"Paternity Leave",'LEAVE LOG'!G$1:G$1048573,"Approved") -> 0 | G11: =SUMIFS('LEAVE LOG'!F$1:F$1048573,'LEAVE LOG'!B$1:B$1048573,A11,'LEAVE LOG'!C$1:C$1048573,"Maternity Leave",'LEAVE LOG'!G$1:G$1048573,"Approved") -> 0 | H11: =SUMIFS('LEAVE LOG'!F$1:F$1048573,'LEAVE LOG'!B$1:B$1048573,A11,'LEAVE LOG'!C$1:C$1048573,"Marital Leave",'LEAVE LOG'!G$1:G$1048573,"Approved") -> 0 | I11: =SUMIFS('LEAVE LOG'!F$1:F$1048573,'LEAVE LOG'!B$1:B$1048573,A11,'LEAVE LOG'!C$1:C$1048573,"Compassionate Leave",'LEAVE LOG'!G$1:G$1048573,"Approved") -> 0
A12: =EMPLOYEES!B12 -> Adedayo Olajumoke | B12: =SUMIFS('LEAVE LOG'!F$1:F$1048573,'LEAVE LOG'!B$1:B$1048573,A12,'LEAVE LOG'!C$1:C$1048573,"Sick Leave",'LEAVE LOG'!G$1:G$1048573,"Approved") -> 0 | C12: =5-B12 -> 5 | D12: =SUMIFS('LEAVE LOG'!F$1:F$1048573,'LEAVE LOG'!B$1:B$1048573,A12,'LEAVE LOG'!C$1:C$1048573,"Annual Leave",'LEAVE LOG'!G$1:G$1048573,"Approved") -> 4 | E12: =10-D12 -> 6 | F12: =SUMIFS('LEAVE LOG'!F$1:F$1048573,'LEAVE LOG'!B$1:B$1048573,A12,'LEAVE LOG'!C$1:C$1048573,"Paternity Leave",'LEAVE LOG'!G$1:G$1048573,"Approved") -> 0 | G12: =SUMIFS('LEAVE LOG'!F$1:F$1048573,'LEAVE LOG'!B$1:B$1048573,A12,'LEAVE LOG'!C$1:C$1048573,"Maternity Leave",'LEAVE LOG'!G$1:G$1048573,"Approved") -> 0 | H12: =SUMIFS('LEAVE LOG'!F$1:F$1048573,'LEAVE LOG'!B$1:B$1048573,A12,'LEAVE LOG'!C$1:C$1048573,"Marital Leave",'LEAVE LOG'!G$1:G$1048573,"Approved") -> 0 | I12: =SUMIFS('LEAVE LOG'!F$1:F$1048573,'LEAVE LOG'!B$1:B$1048573,A12,'LEAVE LOG'!C$1:C$1048573,"Compassionate Leave",'LEAVE LOG'!G$1:G$1048573,"Approved") -> 0
A13: =EMPLOYEES!B13 -> Adedayo Tolulope Adebisi | B13: =SUMIFS('LEAVE LOG'!F$1:F$1048573,'LEAVE LOG'!B$1:B$1048573,A13,'LEAVE LOG'!C$1:C$1048573,"Sick Leave",'LEAVE LOG'!G$1:G$1048573,"Approved") -> 0 | C13: =5-B13 -> 5 | D13: =SUMIFS('LEAVE LOG'!F$1:F$1048573,'LEAVE LOG'!B$1:B$1048573,A13,'LEAVE LOG'!C$1:C$1048573,"Annual Leave",'LEAVE LOG'!G$1:G$1048573,"Approved") -> 0 | E13: =10-D13 -> 10 | F13: =SUMIFS('LEAVE LOG'!F$1:F$1048573,'LEAVE LOG'!B$1:B$1048573,A13,'LEAVE LOG'!C$1:C$1048573,"Paternity Leave",'LEAVE LOG'!G$1:G$1048573,"Approved") -> 0 | G13: =SUMIFS('LEAVE LOG'!F$1:F$1048573,'LEAVE LOG'!B$1:B$1048573,A13,'LEAVE LOG'!C$1:C$1048573,"Maternity Leave",'LEAVE LOG'!G$1:G$1048573,"Approved") -> 0 | H13: =SUMIFS('LEAVE LOG'!F$1:F$1048573,'LEAVE LOG'!B$1:B$1048573,A13,'LEAVE LOG'!C$1:C$1048573,"Marital Leave",'LEAVE LOG'!G$1:G$1048573,"Approved") -> 0 | I13: =SUMIFS('LEAVE LOG'!F$1:F$1048573,'LEAVE LOG'!B$1:B$1048573,A13,'LEAVE LOG'!C$1:C$1048573,"Compassionate Leave",'LEAVE LOG'!G$1:G$1048573,"Approved") -> 0
... A104: =EMPLOYEES!B104 -> Kudirat Brown-Birena | B104: =SUMIFS('LEAVE LOG'!F$1:F$1048573,'LEAVE LOG'!B$1:B$1048573,A104,'LEAVE LOG'!C$1:C$1048573,"Sick Leave",'LEAVE LOG'!G$1:G$1048573,"Approved") -> 0 | C104: =5-B104 -> 5 | D104: =SUMIFS('LEAVE LOG'!F$1:F$1048573,'LEAVE LOG'!B$1:B$1048573,A104,'LEAVE LOG'!C$1:C$1048573,"Annual Leave",'LEAVE LOG'!G$1:G$1048573,"Approved") -> 0 | E104: =10-D104 -> 10 | F104: =SUMIFS('LEAVE LOG'!F$1:F$1048573,'LEAVE LOG'!B$1:B$1048573,A104,'LEAVE LOG'!C$1:C$1048573,"Paternity Leave",'LEAVE LOG'!G$1:G$1048573,"Approved") -> 0 | G104: =SUMIFS('LEAVE LOG'!F$1:F$1048573,'LEAVE LOG'!B$1:B$1048573,A104,'LEAVE LOG'!C$1:C$1048573,"Maternity Leave",'LEAVE LOG'!G$1:G$1048573,"Approved") -> 0 | H104: =SUMIFS('LEAVE LOG'!F$1:F$1048573,'LEAVE LOG'!B$1:B$1048573,A104,'LEAVE LOG'!C$1:C$1048573,"Marital Leave",'LEAVE LOG'!G$1:G$1048573,"Approved") -> 0 | I104: =SUMIFS('LEAVE LOG'!F$1:F$1048573,'LEAVE LOG'!B$1:B$1048573,A104,'LEAVE LOG'!C$1:C$1048573,"Compassionate Leave",'LEAVE LOG'!G$1:G$1048573,"Approved") -> 0
B105: =SUMIFS('LEAVE LOG'!F$1:F$1048573,'LEAVE LOG'!B$1:B$1048573,A105,'LEAVE LOG'!C$1:C$1048573,"Sick Leave",'LEAVE LOG'!G$1:G$1048573,"Approved") -> 0 | C105: =5-B105 -> 5 | D105: =SUMIFS('LEAVE LOG'!F$1:F$1048573,'LEAVE LOG'!B$1:B$1048573,A105,'LEAVE LOG'!C$1:C$1048573,"Annual Leave",'LEAVE LOG'!G$1:G$1048573,"Approved") -> 0 | E105: =10-D105 -> 10 | F105: =SUMIFS('LEAVE LOG'!F$1:F$1048573,'LEAVE LOG'!B$1:B$1048573,A105,'LEAVE LOG'!C$1:C$1048573,"Paternity Leave",'LEAVE LOG'!G$1:G$1048573,"Approved") -> 0 | G105: =SUMIFS('LEAVE LOG'!F$1:F$1048573,'LEAVE LOG'!B$1:B$1048573,A105,'LEAVE LOG'!C$1:C$1048573,"Maternity Leave",'LEAVE LOG'!G$1:G$1048573,"Approved") -> 0 | H105: =SUMIFS('LEAVE LOG'!F$1:F$1048573,'LEAVE LOG'!B$1:B$1048573,A105,'LEAVE LOG'!C$1:C$1048573,"Marital Leave",'LEAVE LOG'!G$1:G$1048573,"Approved") -> 0 | I105: =SUMIFS('LEAVE LOG'!F$1:F$1048573,'LEAVE LOG'!B$1:B$1048573,A105,'LEAVE LOG'!C$1:C$1048573,"Compassionate Leave",'LEAVE LOG'!G$1:G$1048573,"Approved") -> 0
B106: =SUMIFS('LEAVE LOG'!F$1:F$1048573,'LEAVE LOG'!B$1:B$1048573,A106,'LEAVE LOG'!C$1:C$1048573,"Sick Leave",'LEAVE LOG'!G$1:G$1048573,"Approved") -> 0 | C106: =5-B106 -> 5 | D106: =SUMIFS('LEAVE LOG'!F$1:F$1048573,'LEAVE LOG'!B$1:B$1048573,A106,'LEAVE LOG'!C$1:C$1048573,"Annual Leave",'LEAVE LOG'!G$1:G$1048573,"Approved") -> 0 | E106: =10-D106 -> 10 | F106: =SUMIFS('LEAVE LOG'!F$1:F$1048573,'LEAVE LOG'!B$1:B$1048573,A106,'LEAVE LOG'!C$1:C$1048573,"Paternity Leave",'LEAVE LOG'!G$1:G$1048573,"Approved") -> 0 | G106: =SUMIFS('LEAVE LOG'!F$1:F$1048573,'LEAVE LOG'!B$1:B$1048573,A106,'LEAVE LOG'!C$1:C$1048573,"Maternity Leave",'LEAVE LOG'!G$1:G$1048573,"Approved") -> 0 | H106: =SUMIFS('LEAVE LOG'!F$1:F$1048573,'LEAVE LOG'!B$1:B$1048573,A106,'LEAVE LOG'!C$1:C$1048573,"Marital Leave",'LEAVE LOG'!G$1:G$1048573,"Approved") -> 0 | I106: =SUMIFS('LEAVE LOG'!F$1:F$1048573,'LEAVE LOG'!B$1:B$1048573,A106,'LEAVE LOG'!C$1:C$1048573,"Compassionate Leave",'LEAVE LOG'!G$1:G$1048573,"Approved") -> 0
B107: =SUMIFS('LEAVE LOG'!F$1:F$1048573,'LEAVE LOG'!B$1:B$1048573,A107,'LEAVE LOG'!C$1:C$1048573,"Sick Leave",'LEAVE LOG'!G$1:G$1048573,"Approved") -> 0 | C107: =5-B107 -> 5 | D107: =SUMIFS('LEAVE LOG'!F$1:F$1048573,'LEAVE LOG'!B$1:B$1048573,A107,'LEAVE LOG'!C$1:C$1048573,"Annual Leave",'LEAVE LOG'!G$1:G$1048573,"Approved") -> 0 | E107: =10-D107 -> 10 | F107: =SUMIFS('LEAVE LOG'!F$1:F$1048573,'LEAVE LOG'!B$1:B$1048573,A107,'LEAVE LOG'!C$1:C$1048573,"Paternity Leave",'LEAVE LOG'!G$1:G$1048573,"Approved") -> 0 | G107: =SUMIFS('LEAVE LOG'!F$1:F$1048573,'LEAVE LOG'!B$1:B$1048573,A107,'LEAVE LOG'!C$1:C$1048573,"Maternity Leave",'LEAVE LOG'!G$1:G$1048573,"Approved") -> 0 | H107: =SUMIFS('LEAVE LOG'!F$1:F$1048573,'LEAVE LOG'!B$1:B$1048573,A107,'LEAVE LOG'!C$1:C$1048573,"Marital Leave",'LEAVE LOG'!G$1:G$1048573,"Approved") -> 0 | I107: =SUMIFS('LEAVE LOG'!F$1:F$1048573,'LEAVE LOG'!B$1:B$1048573,A107,'LEAVE LOG'!C$1:C$1048573,"Compassionate Leave",'LEAVE LOG'!G$1:G$1048573,"Approved") -> 0
B108: =SUMIFS('LEAVE LOG'!F$1:F$1048573,'LEAVE LOG'!B$1:B$1048573,A108,'LEAVE LOG'!C$1:C$1048573,"Sick Leave",'LEAVE LOG'!G$1:G$1048573,"Approved") -> 0 | C108: =5-B108 -> 5 | D108: =SUMIFS('LEAVE LOG'!F$1:F$1048573,'LEAVE LOG'!B$1:B$1048573,A108,'LEAVE LOG'!C$1:C$1048573,"Annual Leave",'LEAVE LOG'!G$1:G$1048573,"Approved") -> 0 | E108: =10-D108 -> 10 | F108: =SUMIFS('LEAVE LOG'!F$1:F$1048573,'LEAVE LOG'!B$1:B$1048573,A108,'LEAVE LOG'!C$1:C$1048573,"Paternity Leave",'LEAVE LOG'!G$1:G$1048573,"Approved") -> 0 | G108: =SUMIFS('LEAVE LOG'!F$1:F$1048573,'LEAVE LOG'!B$1:B$1048573,A108,'LEAVE LOG'!C$1:C$1048573,"Maternity Leave",'LEAVE LOG'!G$1:G$1048573,"Approved") -> 0 | H108: =SUMIFS('LEAVE LOG'!F$1:F$1048573,'LEAVE LOG'!B$1:B$1048573,A108,'LEAVE LOG'!C$1:C$1048573,"Marital Leave",'LEAVE LOG'!G$1:G$1048573,"Approved") -> 0 | I108: =SUMIFS('LEAVE LOG'!F$1:F$1048573,'LEAVE LOG'!B$1:B$1048573,A108,'LEAVE LOG'!C$1:C$1048573,"Compassionate Leave",'LEAVE LOG'!G$1:G$1048573,"Approved") -> 0
B109: =SUMIFS('LEAVE LOG'!F$1:F$1048573,'LEAVE LOG'!B$1:B$1048573,A109,'LEAVE LOG'!C$1:C$1048573,"Sick Leave",'LEAVE LOG'!G$1:G$1048573,"Approved") -> 0 | C109: =5-B109 -> 5 | D109: =SUMIFS('LEAVE LOG'!F$1:F$1048573,'LEAVE LOG'!B$1:B$1048573,A109,'LEAVE LOG'!C$1:C$1048573,"Annual Leave",'LEAVE LOG'!G$1:G$1048573,"Approved") -> 0 | E109: =10-D109 -> 10 | F109: =SUMIFS('LEAVE LOG'!F$1:F$1048573,'LEAVE LOG'!B$1:B$1048573,A109,'LEAVE LOG'!C$1:C$1048573,"Paternity Leave",'LEAVE LOG'!G$1:G$1048573,"Approved") -> 0 | G109: =SUMIFS('LEAVE LOG'!F$1:F$1048573,'LEAVE LOG'!B$1:B$1048573,A109,'LEAVE LOG'!C$1:C$1048573,"Maternity Leave",'LEAVE LOG'!G$1:G$1048573,"Approved") -> 0 | H109: =SUMIFS('LEAVE LOG'!F$1:F$1048573,'LEAVE LOG'!B$1:B$1048573,A109,'LEAVE LOG'!C$1:C$1048573,"Marital Leave",'LEAVE LOG'!G$1:G$1048573,"Approved") -> 0 | I109: =SUMIFS('LEAVE LOG'!F$1:F$1048573,'LEAVE LOG'!B$1:B$1048573,A109,'LEAVE LOG'!C$1:C$1048573,"Compassionate Leave",'LEAVE LOG'!G$1:G$1048573,"Approved") -> 0
B110: =SUMIFS('LEAVE LOG'!F$1:F$1048573,'LEAVE LOG'!B$1:B$1048573,A110,'LEAVE LOG'!C$1:C$1048573,"Sick Leave",'LEAVE LOG'!G$1:G$1048573,"Approved") -> 0 | C110: =5-B110 -> 5 | D110: =SUMIFS('LEAVE LOG'!F$1:F$1048573,'LEAVE LOG'!B$1:B$1048573,A110,'LEAVE LOG'!C$1:C$1048573,"Annual Leave",'LEAVE LOG'!G$1:G$1048573,"Approved") -> 0 | E110: =10-D110 -> 10 | F110: =SUMIFS('LEAVE LOG'!F$1:F$1048573,'LEAVE LOG'!B$1:B$1048573,A110,'LEAVE LOG'!C$1:C$1048573,"Paternity Leave",'LEAVE LOG'!G$1:G$1048573,"Approved") -> 0 | G110: =SUMIFS('LEAVE LOG'!F$1:F$1048573,'LEAVE LOG'!B$1:B$1048573,A110,'LEAVE LOG'!C$1:C$1048573,"Maternity Leave",'LEAVE LOG'!G$1:G$1048573,"Approved") -> 0 | H110: =SUMIFS('LEAVE LOG'!F$1:F$1048573,'LEAVE LOG'!B$1:B$1048573,A110,'LEAVE LOG'!C$1:C$1048573,"Marital Leave",'LEAVE LOG'!G$1:G$1048573,"Approved") -> 0 | I110: =SUMIFS('LEAVE LOG'!F$1:F$1048573,'LEAVE LOG'!B$1:B$1048573,A110,'LEAVE LOG'!C$1:C$1048573,"Compassionate Leave",'LEAVE LOG'!G$1:G$1048573,"Approved") -> 0
B111: =SUMIFS('LEAVE LOG'!F$1:F$1048573,'LEAVE LOG'!B$1:B$1048573,A111,'LEAVE LOG'!C$1:C$1048573,"Sick Leave",'LEAVE LOG'!G$1:G$1048573,"Approved") -> 0 | C111: =5-B111 -> 5 | D111: =SUMIFS('LEAVE LOG'!F$1:F$1048573,'LEAVE LOG'!B$1:B$1048573,A111,'LEAVE LOG'!C$1:C$1048573,"Annual Leave",'LEAVE LOG'!G$1:G$1048573,"Approved") -> 0 | E111: =10-D111 -> 10 | F111: =SUMIFS('LEAVE LOG'!F$1:F$1048573,'LEAVE LOG'!B$1:B$1048573,A111,'LEAVE LOG'!C$1:C$1048573,"Paternity Leave",'LEAVE LOG'!G$1:G$1048573,"Approved") -> 0 | G111: =SUMIFS('LEAVE LOG'!F$1:F$1048573,'LEAVE LOG'!B$1:B$1048573,A111,'LEAVE LOG'!C$1:C$1048573,"Maternity Leave",'LEAVE LOG'!G$1:G$1048573,"Approved") -> 0 | H111: =SUMIFS('LEAVE LOG'!F$1:F$1048573,'LEAVE LOG'!B$1:B$1048573,A111,'LEAVE LOG'!C$1:C$1048573,"Marital Leave",'LEAVE LOG'!G$1:G$1048573,"Approved") -> 0 | I111: =SUMIFS('LEAVE LOG'!F$1:F$1048573,'LEAVE LOG'!B$1:B$1048573,A111,'LEAVE LOG'!C$1:C$1048573,"Compassionate Leave",'LEAVE LOG'!G$1:G$1048573,"Approved") -> 0
B112: =SUMIFS('LEAVE LOG'!F$1:F$1048573,'LEAVE LOG'!B$1:B$1048573,A112,'LEAVE LOG'!C$1:C$1048573,"Sick Leave",'LEAVE LOG'!G$1:G$1048573,"Approved") -> 0 | C112: =5-B112 -> 5 | D112: =SUMIFS('LEAVE LOG'!F$1:F$1048573,'LEAVE LOG'!B$1:B$1048573,A112,'LEAVE LOG'!C$1:C$1048573,"Annual Leave",'LEAVE LOG'!G$1:G$1048573,"Approved") -> 0 | E112: =10-D112 -> 10 | F112: =SUMIFS('LEAVE LOG'!F$1:F$1048573,'LEAVE LOG'!B$1:B$1048573,A112,'LEAVE LOG'!C$1:C$1048573,"Paternity Leave",'LEAVE LOG'!G$1:G$1048573,"Approved") -> 0 | G112: =SUMIFS('LEAVE LOG'!F$1:F$1048573,'LEAVE LOG'!B$1:B$1048573,A112,'LEAVE LOG'!C$1:C$1048573,"Maternity Leave",'LEAVE LOG'!G$1:G$1048573,"Approved") -> 0 | H112: =SUMIFS('LEAVE LOG'!F$1:F$1048573,'LEAVE LOG'!B$1:B$1048573,A112,'LEAVE LOG'!C$1:C$1048573,"Marital Leave",'LEAVE LOG'!G$1:G$1048573,"Approved") -> 0 | I112: =SUMIFS('LEAVE LOG'!F$1:F$1048573,'LEAVE LOG'!B$1:B$1048573,A112,'LEAVE LOG'!C$1:C$1048573,"Compassionate Leave",'LEAVE LOG'!G$1:G$1048573,"Approved") -> 0
B113: =SUMIFS('LEAVE LOG'!F$1:F$1048573,'LEAVE LOG'!B$1:B$1048573,A113,'LEAVE LOG'!C$1:C$1048573,"Sick Leave",'LEAVE LOG'!G$1:G$1048573,"Approved") -> 0 | C113: =5-B113 -> 5 | D113: =SUMIFS('LEAVE LOG'!F$1:F$1048573,'LEAVE LOG'!B$1:B$1048573,A113,'LEAVE LOG'!C$1:C$1048573,"Annual Leave",'LEAVE LOG'!G$1:G$1048573,"Approved") -> 0 | E113: =10-D113 -> 10 | F113: =SUMIFS('LEAVE LOG'!F$1:F$1048573,'LEAVE LOG'!B$1:B$1048573,A113,'LEAVE LOG'!C$1:C$1048573,"Paternity Leave",'LEAVE LOG'!G$1:G$1048573,"Approved") -> 0 | G113: =SUMIFS('LEAVE LOG'!F$1:F$1048573,'LEAVE LOG'!B$1:B$1048573,A113,'LEAVE LOG'!C$1:C$1048573,"Maternity Leave",'LEAVE LOG'!G$1:G$1048573,"Approved") -> 0 | H113: =SUMIFS('LEAVE LOG'!F$1:F$1048573,'LEAVE LOG'!B$1:B$1048573,A113,'LEAVE LOG'!C$1:C$1048573,"Marital Leave",'LEAVE LOG'!G$1:G$1048573,"Approved") -> 0 | I113: =SUMIFS('LEAVE LOG'!F$1:F$1048573,'LEAVE LOG'!B$1:B$1048573,A113,'LEAVE LOG'!C$1:C$1048573,"Compassionate Leave",'LEAVE LOG'!G$1:G$1048573,"Approved") -> 0
B114: =SUMIFS('LEAVE LOG'!F$1:F$1048573,'LEAVE LOG'!B$1:B$1048573,A114,'LEAVE LOG'!C$1:C$1048573,"Sick Leave",'LEAVE LOG'!G$1:G$1048573,"Approved") -> 0 | C114: =5-B114 -> 5 | D114: =SUMIFS('LEAVE LOG'!F$1:F$1048573,'LEAVE LOG'!B$1:B$1048573,A114,'LEAVE LOG'!C$1:C$1048573,"Annual Leave",'LEAVE LOG'!G$1:G$1048573,"Approved") -> 0 | E114: =10-D114 -> 10 | F114: =SUMIFS('LEAVE LOG'!F$1:F$1048573,'LEAVE LOG'!B$1:B$1048573,A114,'LEAVE LOG'!C$1:C$1048573,"Paternity Leave",'LEAVE LOG'!G$1:G$1048573,"Approved") -> 0 | G114: =SUMIFS('LEAVE LOG'!F$1:F$1048573,'LEAVE LOG'!B$1:B$1048573,A114,'LEAVE LOG'!C$1:C$1048573,"Maternity Leave",'LEAVE LOG'!G$1:G$1048573,"Approved") -> 0 | H114: =SUMIFS('LEAVE LOG'!F$1:F$1048573,'LEAVE LOG'!B$1:B$1048573,A114,'LEAVE LOG'!C$1:C$1048573,"Marital Leave",'LEAVE LOG'!G$1:G$1048573,"Approved") -> 0 | I114: =SUMIFS('LEAVE LOG'!F$1:F$1048573,'LEAVE LOG'!B$1:B$1048573,A114,'LEAVE LOG'!C$1:C$1048573,"Compassionate Leave",'LEAVE LOG'!G$1:G$1048573,"Approved") -> 0
B115: =SUMIFS('LEAVE LOG'!F$1:F$1048573,'LEAVE LOG'!B$1:B$1048573,A115,'LEAVE LOG'!C$1:C$1048573,"Sick Leave",'LEAVE LOG'!G$1:G$1048573,"Approved") -> 0 | C115: =5-B115 -> 5 | D115: =SUMIFS('LEAVE LOG'!F$1:F$1048573,'LEAVE LOG'!B$1:B$1048573,A115,'LEAVE LOG'!C$1:C$1048573,"Annual Leave",'LEAVE LOG'!G$1:G$1048573,"Approved") -> 0 | E115: =10-D115 -> 10 | F115: =SUMIFS('LEAVE LOG'!F$1:F$1048573,'LEAVE LOG'!B$1:B$1048573,A115,'LEAVE LOG'!C$1:C$1048573,"Paternity Leave",'LEAVE LOG'!G$1:G$1048573,"Approved") -> 0 | G115: =SUMIFS('LEAVE LOG'!F$1:F$1048573,'LEAVE LOG'!B$1:B$1048573,A115,'LEAVE LOG'!C$1:C$1048573,"Maternity Leave",'LEAVE LOG'!G$1:G$1048573,"Approved") -> 0 | H115: =SUMIFS('LEAVE LOG'!F$1:F$1048573,'LEAVE LOG'!B$1:B$1048573,A115,'LEAVE LOG'!C$1:C$1048573,"Marital Leave",'LEAVE LOG'!G$1:G$1048573,"Approved") -> 0 | I115: =SUMIFS('LEAVE LOG'!F$1:F$1048573,'LEAVE LOG'!B$1:B$1048573,A115,'LEAVE LOG'!C$1:C$1048573,"Compassionate Leave",'LEAVE LOG'!G$1:G$1048573,"Approved") -> 0
B116: =SUMIFS('LEAVE LOG'!F$1:F$1048573,'LEAVE LOG'!B$1:B$1048573,A116,'LEAVE LOG'!C$1:C$1048573,"Sick Leave",'LEAVE LOG'!G$1:G$1048573,"Approved") -> 0 | C116: =5-B116 -> 5 | D116: =SUMIFS('LEAVE LOG'!F$1:F$1048573,'LEAVE LOG'!B$1:B$1048573,A116,'LEAVE LOG'!C$1:C$1048573,"Annual Leave",'LEAVE LOG'!G$1:G$1048573,"Approved") -> 0 | E116: =10-D116 -> 10 | F116: =SUMIFS('LEAVE LOG'!F$1:F$1048573,'LEAVE LOG'!B$1:B$1048573,A116,'LEAVE LOG'!C$1:C$1048573,"Paternity Leave",'LEAVE LOG'!G$1:G$1048573,"Approved") -> 0 | G116: =SUMIFS('LEAVE LOG'!F$1:F$1048573,'LEAVE LOG'!B$1:B$1048573,A116,'LEAVE LOG'!C$1:C$1048573,"Maternity Leave",'LEAVE LOG'!G$1:G$1048573,"Approved") -> 0 | H116: =SUMIFS('LEAVE LOG'!F$1:F$1048573,'LEAVE LOG'!B$1:B$1048573,A116,'LEAVE LOG'!C$1:C$1048573,"Marital Leave",'LEAVE LOG'!G$1:G$1048573,"Approved") -> 0 | I116: =SUMIFS('LEAVE LOG'!F$1:F$1048573,'LEAVE LOG'!B$1:B$1048573,A116,'LEAVE LOG'!C$1:C$1048573,"Compassionate Leave",'LEAVE LOG'!G$1:G$1048573,"Approved") -> 0
... B140: =SUMIFS('LEAVE LOG'!F$1:F$1048573,'LEAVE LOG'!B$1:B$1048573,A140,'LEAVE LOG'!C$1:C$1048573,"Sick Leave",'LEAVE LOG'!G$1:G$1048573,"Approved") -> 0 | C140: =5-B140 -> 5 | D140: =SUMIFS('LEAVE LOG'!F$1:F$1048573,'LEAVE LOG'!B$1:B$1048573,A140,'LEAVE LOG'!C$1:C$1048573,"Annual Leave",'LEAVE LOG'!G$1:G$1048573,"Approved") -> 0 | E140: =10-D140 -> 10 | F140: =SUMIFS('LEAVE LOG'!F$1:F$1048573,'LEAVE LOG'!B$1:B$1048573,A140,'LEAVE LOG'!C$1:C$1048573,"Paternity Leave",'LEAVE LOG'!G$1:G$1048573,"Approved") -> 0 | G140: =SUMIFS('LEAVE LOG'!F$1:F$1048573,'LEAVE LOG'!B$1:B$1048573,A140,'LEAVE LOG'!C$1:C$1048573,"Maternity Leave",'LEAVE LOG'!G$1:G$1048573,"Approved") -> 0 | H140: =SUMIFS('LEAVE LOG'!F$1:F$1048573,'LEAVE LOG'!B$1:B$1048573,A140,'LEAVE LOG'!C$1:C$1048573,"Marital Leave",'LEAVE LOG'!G$1:G$1048573,"Approved") -> 0 | I140: =SUMIFS('LEAVE LOG'!F$1:F$1048573,'LEAVE LOG'!B$1:B$1048573,A140,'LEAVE LOG'!C$1:C$1048573,"Compassionate Leave",'LEAVE LOG'!G$1:G$1048573,"Approved") -> 0
I141: =SUMIFS('LEAVE LOG'!F$1:F$1048573,'LEAVE LOG'!B$1:B$1048573,A141,'LEAVE LOG'!C$1:C$1048573,"Compassionate Leave",'LEAVE LOG'!G$1:G$1048573,"Approved") -> 0
